Workbook
Name Slicer_Region: #N/A
Name Timeline_Order_Date: #N/A

Sheet Sales Raw Data
A1: Order ID | B1: Order Date | C1: Customer ID | D1: Product ID | E1: Employee ID | F1: Region | G1: Order Status | H1: Payment Mode | I1: Quantity | J1: Unit Price | K1: Discount % | L1: Product Name | M1: Employee Name | N1: Customer Name | O1: Gross Sales | P1: Discount | Q1: Net Sale | R1: Total Cost | S1: Profit | T1: profit% | U1: Month | V1: Year | W1: Days | X1: Weekned/Weekday | Y1: Sale Eligilblity | Z1: Retured
A2: O1001 | B2: 46027 | C2: C001 | D2: P001 | E2: E001 | F2: Hyderabad | G2: Delivered | H2: Online | I2: 5 | J2: 50000 | K2: 0.05 | L2: =_xlfn.XLOOKUP(Sales_Table[[#This Row],[Product ID]],Products[Product ID],Products[Product Name],"N",0) -> Laptop | M2: =_xlfn.XLOOKUP(Sales_Table[[#This Row],[Employee ID]],Employees[Employee ID],Employees[Employee Name],"N",0) -> Rahul Kumar | N2: =_xlfn.XLOOKUP(Sales_Table[[#This Row],[Customer ID]],Table22[Customer ID],Table22[Customer Name]) -> ABC Technologies | O2: =Sales_Table[[#This Row],[Unit Price]]*Sales_Table[[#This Row],[Quantity]] -> 250000 | P2: =Sales_Table[[#This Row],[Gross Sales]]*Sales_Table[[#This Row],[Discount %]] -> 12500 | Q2: =Sales_Table[[#This Row],[Gross Sales]]-Sales_Table[[#This Row],[Discount]] -> 237500 | R2: =VLOOKUP(Sales_Table[[#This Row],[Product ID]],Products[],5,FALSE)*Sales_Table[[#This Row],[Quantity]] -> 195000 | S2: =Sales_Table[[#This Row],[Net Sale]]-Sales_Table[[#This Row],[Total Cost]] -> 42500 | T2: =Sales_Table[[#This Row],[Profit]]/Sales_Table[[#This Row],[Net Sale]] -> 0.17894737 | U2: =TEXT(Sales_Table[[#This Row],[Order Date]],"mmmm-YYYY") -> January-2026 | V2: =YEAR(Sales_Table[[#This Row],[Month]]) -> 2026 | W2: =TEXT(Sales_Table[[#This Row],[Order Date]],"DDDD") -> Monday | X2: =IF(OR(Sales_Table[[#This Row],[Days ]]=$W$5,Sales_Table[[#This Row],[Days ]]=$W$8),"Weekned","Weekday") -> Weekday | Y2: =IF(Sales_Table[[#This Row],[Order Status]]="Delivered","Y","N") -> Y | Z2: =IF(Sales_Table[[#This Row],[Order Status]]="Returned","Yes","N") -> N
A3: O1002 | B3: 46028 | C3: C002 | D3: P002 | E3: E002 | F3: Chennai | G3: Delivered | H3: UPI | I3: 8 | J3: 25000 | K3: 0.1 | L3: =_xlfn.XLOOKUP(Sales_Table[[#This Row],[Product ID]],Products[Product ID],Products[Product Name],"N",0) -> Monitor | M3: =_xlfn.XLOOKUP(Sales_Table[[#This Row],[Employee ID]],Employees[Employee ID],Employees[Employee Name],"N",0) -> Priya Sharma | N3: =_xlfn.XLOOKUP(Sales_Table[[#This Row],[Customer ID]],Table22[Customer ID],Table22[Customer Name]) -> Sri Lakshmi Traders | O3: =Sales_Table[[#This Row],[Unit Price]]*Sales_Table[[#This Row],[Quantity]] -> 200000 | P3: =Sales_Table[[#This Row],[Gross Sales]]*Sales_Table[[#This Row],[Discount %]] -> 20000 | Q3: =Sales_Table[[#This Row],[Gross Sales]]-Sales_Table[[#This Row],[Discount]] -> 180000 | R3: =VLOOKUP(Sales_Table[[#This Row],[Product ID]],Products[],5,FALSE)*Sales_Table[[#This Row],[Quantity]] -> 152000 | S3: =Sales_Table[[#This Row],[Net Sale]]-Sales_Table[[#This Row],[Total Cost]] -> 28000 | T3: =Sales_Table[[#This Row],[Profit]]/Sales_Table[[#This Row],[Net Sale]] -> 0.15555556 | U3: =TEXT(Sales_Table[[#This Row],[Order Date]],"mmmm-YYYY") -> January-2026 | V3: =YEAR(Sales_Table[[#This Row],[Month]]) -> 2026 | W3: =TEXT(Sales_Table[[#This Row],[Order Date]],"DDDD") -> Tuesday | X3: =IF(OR(Sales_Table[[#This Row],[Days ]]=$W$5,Sales_Table[[#This Row],[Days ]]=$W$8),"Weekned","Weekday") -> Weekday | Y3: =IF(Sales_Table[[#This Row],[Order Status]]="Delivered","Y","N") -> Y | Z3: =IF(Sales_Table[[#This Row],[Order Status]]="Returned","Yes","N") -> N
A4: O1003 | B4: 46030 | C4: C003 | D4: P003 | E4: E003 | F4: Bangalore | G4: Delivered | H4: Card | I4: 15 | J4: 5000 | K4: 0.05 | L4: =_xlfn.XLOOKUP(Sales_Table[[#This Row],[Product ID]],Products[Product ID],Products[Product Name],"N",0) -> Keyboard | M4: =_xlfn.XLOOKUP(Sales_Table[[#This Row],[Employee ID]],Employees[Employee ID],Employees[Employee Name],"N",0) -> Arjun Reddy | N4: =_xlfn.XLOOKUP(Sales_Table[[#This Row],[Customer ID]],Table22[Customer ID],Table22[Customer Name]) -> Vertex Solutions | O4: =Sales_Table[[#This Row],[Unit Price]]*Sales_Table[[#This Row],[Quantity]] -> 75000 | P4: =Sales_Table[[#This Row],[Gross Sales]]*Sales_Table[[#This Row],[Discount %]] -> 3750 | Q4: =Sales_Table[[#This Row],[Gross Sales]]-Sales_Table[[#This Row],[Discount]] -> 71250 | R4: =VLOOKUP(Sales_Table[[#This Row],[Product ID]],Products[],5,FALSE)*Sales_Table[[#This Row],[Quantity]] -> 52500 | S4: =Sales_Table[[#This Row],[Net Sale]]-Sales_Table[[#This Row],[Total Cost]] -> 18750 | T4: =Sales_Table[[#This Row],[Profit]]/Sales_Table[[#This Row],[Net Sale]] -> 0.26315789 | U4: =TEXT(Sales_Table[[#This Row],[Order Date]],"mmmm-YYYY") -> January-2026 | V4: =YEAR(Sales_Table[[#This Row],[Month]]) -> 2026 | W4: =TEXT(Sales_Table[[#This Row],[Order Date]],"DDDD") -> Thursday | X4: =IF(OR(Sales_Table[[#This Row],[Days ]]=$W$5,Sales_Table[[#This Row],[Days ]]=$W$8),"Weekned","Weekday") -> Weekday | Y4: =IF(Sales_Table[[#This Row],[Order Status]]="Delivered","Y","N") -> Y | Z4: =IF(Sales_Table[[#This Row],[Order Status]]="Returned","Yes","N") -> N
A5: O1004 | B5: 46032 | C5: C004 | D5: P004 | E5: E004 | F5: Pune | G5: Delivered | H5: Cash | I5: 20 | J5: 2000 | K5: 0 | L5: =_xlfn.XLOOKUP(Sales_Table[[#This Row],[Product ID]],Products[Product ID],Products[Product Name],"N",0) -> Mouse | M5: =_xlfn.XLOOKUP(Sales_Table[[#This Row],[Employee ID]],Employees[Employee ID],Employees[Employee Name],"N",0) -> Sneha Patel | N5: =_xlfn.XLOOKUP(Sales_Table[[#This Row],[Customer ID]],Table22[Customer ID],Table22[Customer Name]) -> Royal Enterprises | O5: =Sales_Table[[#This Row],[Unit Price]]*Sales_Table[[#This Row],[Quantity]] -> 40000 | P5: =Sales_Table[[#This Row],[Gross Sales]]*Sales_Table[[#This Row],[Discount %]] -> 0 | Q5: =Sales_Table[[#This Row],[Gross Sales]]-Sales_Table[[#This Row],[Discount]] -> 40000 | R5: =VLOOKUP(Sales_Table[[#This Row],[Product ID]],Products[],5,FALSE)*Sales_Table[[#This Row],[Quantity]] -> 24000 | S5: =Sales_Table[[#This Row],[Net Sale]]-Sales_Table[[#This Row],[Total Cost]] -> 16000 | T5: =Sales_Table[[#This Row],[Profit]]/Sales_Table[[#This Row],[Net Sale]] -> 0.4 | U5: =TEXT(Sales_Table[[#This Row],[Order Date]],"mmmm-YYYY") -> January-2026 | V5: =YEAR(Sales_Table[[#This Row],[Month]]) -> 2026 | W5: =TEXT(Sales_Table[[#This Row],[Order Date]],"DDDD") -> Saturday | X5: =IF(OR(Sales_Table[[#This Row],[Days ]]=$W$5,Sales_Table[[#This Row],[Days ]]=$W$8),"Weekned","Weekday") -> Weekned | Y5: =IF(Sales_Table[[#This Row],[Order Status]]="Delivered","Y","N") -> Y | Z5: =IF(Sales_Table[[#This Row],[Order Status]]="Returned","Yes","N") -> N
A6: O1005 | B6: 46034 | C6: C005 | D6: P005 | E6: E005 | F6: Hyderabad | G6: Delivered | H6: Online | I6: 6 | J6: 35000 | K6: 0.08 | L6: =_xlfn.XLOOKUP(Sales_Table[[#This Row],[Product ID]],Products[Product ID],Products[Product Name],"N",0) -> Printer | M6: =_xlfn.XLOOKUP(Sales_Table[[#This Row],[Employee ID]],Employees[Employee ID],Employees[Employee Name],"N",0) -> Kiran Rao | N6: =_xlfn.XLOOKUP(Sales_Table[[#This Row],[Customer ID]],Table22[Customer ID],Table22[Customer Name]) -> TechNova Pvt Ltd | O6: =Sales_Table[[#This Row],[Unit Price]]*Sales_Table[[#This Row],[Quantity]] -> 210000 | P6: =Sales_Table[[#This Row],[Gross Sales]]*Sales_Table[[#This Row],[Discount %]] -> 16800 | Q6: =Sales_Table[[#This Row],[Gross Sales]]-Sales_Table[[#This Row],[Discount]] -> 193200 | R6: =VLOOKUP(Sales_Table[[#This Row],[Product ID]],Products[],5,FALSE)*Sales_Table[[#This Row],[Quantity]] -> 162000 | S6: =Sales_Table[[#This Row],[Net Sale]]-Sales_Table[[#This Row],[Total Cost]] -> 31200 | T6: =Sales_Table[[#This Row],[Profit]]/Sales_Table[[#This Row],[Net Sale]] -> 0.16149068 | U6: =TEXT(Sales_Table[[#This Row],[Order Date]],"mmmm-YYYY") -> January-2026 | V6: =YEAR(Sales_Table[[#This Row],[Month]]) -> 2026 | W6: =TEXT(Sales_Table[[#This Row],[Order Date]],"DDDD") -> Monday | X6: =IF(OR(Sales_Table[[#This Row],[Days ]]=$W$5,Sales_Table[[#This Row],[Days ]]=$W$8),"Weekned","Weekday") -> Weekday | Y6: =IF(Sales_Table[[#This Row],[Order Status]]="Delivered","Y","N") -> Y | Z6: =IF(Sales_Table[[#This Row],[Order Status]]="Returned","Yes","N") -> N
A7: O1006 | B7: 46037 | C7: C006 | D7: P006 | E7: E006 | F7: Chennai | G7: Delivered | H7: UPI | I7: 12 | J7: 8000 | K7: 0.05 | L7: =_xlfn.XLOOKUP(Sales_Table[[#This Row],[Product ID]],Products[Product ID],Products[Product Name],"N",0) -> Headset | M7: =_xlfn.XLOOKUP(Sales_Table[[#This Row],[Employee ID]],Employees[Employee ID],Employees[Employee Name],"N",0) -> Anjali Singh | N7: =_xlfn.XLOOKUP(Sales_Table[[#This Row],[Customer ID]],Table22[Customer ID],Table22[Customer Name]) -> Metro Computers | O7: =Sales_Table[[#This Row],[Unit Price]]*Sales_Table[[#This Row],[Quantity]] -> 96000 | P7: =Sales_Table[[#This Row],[Gross Sales]]*Sales_Table[[#This Row],[Discount %]] -> 4800 | Q7: =Sales_Table[[#This Row],[Gross Sales]]-Sales_Table[[#This Row],[Discount]] -> 91200 | R7: =VLOOKUP(Sales_Table[[#This Row],[Product ID]],Products[],5,FALSE)*Sales_Table[[#This Row],[Quantity]] -> 62400 | S7: =Sales_Table[[#This Row],[Net Sale]]-Sales_Table[[#This Row],[Total Cost]] -> 28800 | T7: =Sales_Table[[#This Row],[Profit]]/Sales_Table[[#This Row],[Net Sale]] -> 0.31578947 | U7: =TEXT(Sales_Table[[#This Row],[Order Date]],"mmmm-YYYY") -> January-2026 | V7: =YEAR(Sales_Table[[#This Row],[Month]]) -> 2026 | W7: =TEXT(Sales_Table[[#This Row],[Order Date]],"DDDD") -> Thursday | X7: =IF(OR(Sales_Table[[#This Row],[Days ]]=$W$5,Sales_Table[[#This Row],[Days ]]=$W$8),"Weekned","Weekday") -> Weekday | Y7: =IF(Sales_Table[[#This Row],[Order Status]]="Delivered","Y","N") -> Y | Z7: =IF(Sales_Table[[#This Row],[Order Status]]="Returned","Yes","N") -> N
A8: O1007 | B8: 46040 | C8: C007 | D8: P001 | E8: E002 | F8: Bangalore | G8: Delivered | H8: Card | I8: 4 | J8: 50000 | K8: 0.1 | L8: =_xlfn.XLOOKUP(Sales_Table[[#This Row],[Product ID]],Products[Product ID],Products[Product Name],"N",0) -> Laptop | M8: =_xlfn.XLOOKUP(Sales_Table[[#This Row],[Employee ID]],Employees[Employee ID],Employees[Employee Name],"N",0) -> Priya Sharma | N8: =_xlfn.XLOOKUP(Sales_Table[[#This Row],[Customer ID]],Table22[Customer ID],Table22[Customer Name]) -> Future Systems | O8: =Sales_Table[[#This Row],[Unit Price]]*Sales_Table[[#This Row],[Quantity]] -> 200000 | P8: =Sales_Table[[#This Row],[Gross Sales]]*Sales_Table[[#This Row],[Discount %]] -> 20000 | Q8: =Sales_Table[[#This Row],[Gross Sales]]-Sales_Table[[#This Row],[Discount]] -> 180000 | R8: =VLOOKUP(Sales_Table[[#This Row],[Product ID]],Products[],5,FALSE)*Sales_Table[[#This Row],[Quantity]] -> 156000 | S8: =Sales_Table[[#This Row],[Net Sale]]-Sales_Table[[#This Row],[Total Cost]] -> 24000 | T8: =Sales_Table[[#This Row],[Profit]]/Sales_Table[[#This Row],[Net Sale]] -> 0.13333333 | U8: =TEXT(Sales_Table[[#This Row],[Order Date]],"mmmm-YYYY") -> January-2026 | V8: =YEAR(Sales_Table[[#This Row],[Month]]) -> 2026 | W8: =TEXT(Sales_Table[[#This Row],[Order Date]],"DDDD") -> Sunday | X8: =IF(OR(Sales_Table[[#This Row],[Days ]]=$W$5,Sales_Table[[#This Row],[Days ]]=$W$8),"Weekned","Weekday") -> Weekned | Y8: =IF(Sales_Table[[#This Row],[Order Status]]="Delivered","Y","N") -> Y | Z8: =IF(Sales_Table[[#This Row],[Order Status]]="Returned","Yes","N") -> N
A9: O1008 | B9: 46042 | C9: C008 | D9: P002 | E9: E003 | F9: Pune | G9: Delivered | H9: Online | I9: 10 | J9: 25000 | K9: 0.12 | L9: =_xlfn.XLOOKUP(Sales_Table[[#This Row],[Product ID]],Products[Product ID],Products[Product Name],"N",0) -> Monitor | M9: =_xlfn.XLOOKUP(Sales_Table[[#This Row],[Employee ID]],Employees[Employee ID],Employees[Employee Name],"N",0) -> Arjun Reddy | N9: =_xlfn.XLOOKUP(Sales_Table[[#This Row],[Customer ID]],Table22[Customer ID],Table22[Customer Name]) -> Prime Digital | O9: =Sales_Table[[#This Row],[Unit Price]]*Sales_Table[[#This Row],[Quantity]] -> 250000 | P9: =Sales_Table[[#This Row],[Gross Sales]]*Sales_Table[[#This Row],[Discount %]] -> 30000 | Q9: =Sales_Table[[#This Row],[Gross Sales]]-Sales_Table[[#This Row],[Discount]] -> 220000 | R9: =VLOOKUP(Sales_Table[[#This Row],[Product ID]],Products[],5,FALSE)*Sales_Table[[#This Row],[Quantity]] -> 190000 | S9: =Sales_Table[[#This Row],[Net Sale]]-Sales_Table[[#This Row],[Total Cost]] -> 30000 | T9: =Sales_Table[[#This Row],[Profit]]/Sales_Table[[#This Row],[Net Sale]] -> 0.13636364 | U9: =TEXT(Sales_Table[[#This Row],[Order Date]],"mmmm-YYYY") -> January-2026 | V9: =YEAR(Sales_Table[[#This Row],[Month]]) -> 2026 | W9: =TEXT(Sales_Table[[#This Row],[Order Date]],"DDDD") -> Tuesday | X9: =IF(OR(Sales_Table[[#This Row],[Days ]]=$W$5,Sales_Table[[#This Row],[Days ]]=$W$8),"Weekned","Weekday") -> Weekday | Y9: =IF(Sales_Table[[#This Row],[Order Status]]="Delivered","Y","N") -> Y | Z9: =IF(Sales_Table[[#This Row],[Order Status]]="Returned","Yes","N") -> N
A10: O1009 | B10: 46044 | C10: C009 | D10: P003 | E10: E004 | F10: Hyderabad | G10: Delivered | H10: UPI | I10: 25 | J10: 5000 | K10: 0.05 | L10: =_xlfn.XLOOKUP(Sales_Table[[#This Row],[Product ID]],Products[Product ID],Products[Product Name],"N",0) -> Keyboard | M10: =_xlfn.XLOOKUP(Sales_Table[[#This Row],[Employee ID]],Employees[Employee ID],Employees[Employee Name],"N",0) -> Sneha Patel | N10: =_xlfn.XLOOKUP(Sales_Table[[#This Row],[Customer ID]],Table22[Customer ID],Table22[Customer Name]) -> Smart World | O10: =Sales_Table[[#This Row],[Unit Price]]*Sales_Table[[#This Row],[Quantity]] -> 125000 | P10: =Sales_Table[[#This Row],[Gross Sales]]*Sales_Table[[#This Row],[Discount %]] -> 6250 | Q10: =Sales_Table[[#This Row],[Gross Sales]]-Sales_Table[[#This Row],[Discount]] -> 118750 | R10: =VLOOKUP(Sales_Table[[#This Row],[Product ID]],Products[],5,FALSE)*Sales_Table[[#This Row],[Quantity]] -> 87500 | S10: =Sales_Table[[#This Row],[Net Sale]]-Sales_Table[[#This Row],[Total Cost]] -> 31250 | T10: =Sales_Table[[#This Row],[Profit]]/Sales_Table[[#This Row],[Net Sale]] -> 0.26315789 | U10: =TEXT(Sales_Table[[#This Row],[Order Date]],"mmmm-YYYY") -> January-2026 | V10: =YEAR(Sales_Table[[#This Row],[Month]]) -> 2026 | W10: =TEXT(Sales_Table[[#This Row],[Order Date]],"DDDD") -> Thursday | X10: =IF(OR(Sales_Table[[#This Row],[Days ]]=$W$5,Sales_Table[[#This Row],[Days ]]=$W$8),"Weekned","Weekday") -> Weekday | Y10: =IF(Sales_Table[[#This Row],[Order Status]]="Delivered","Y","N") -> Y | Z10: =IF(Sales_Table[[#This Row],[Order Status]]="Returned","Yes","N") -> N
A11: O1010 | B11: 46047 | C11: C010 | D11: P004 | E11: E005 | F11: Chennai | G11: Delivered | H11: Cash | I11: 30 | J11: 2000 | K11: 0 | L11: =_xlfn.XLOOKUP(Sales_Table[[#This Row],[Product ID]],Products[Product ID],Products[Product Name],"N",0) -> Mouse | M11: =_xlfn.XLOOKUP(Sales_Table[[#This Row],[Employee ID]],Employees[Employee ID],Employees[Employee Name],"N",0) -> Kiran Rao | N11: =_xlfn.XLOOKUP(Sales_Table[[#This Row],[Customer ID]],Table22[Customer ID],Table22[Customer Name]) -> NextGen Solutions | O11: =Sales_Table[[#This Row],[Unit Price]]*Sales_Table[[#This Row],[Quantity]] -> 60000 | P11: =Sales_Table[[#This Row],[Gross Sales]]*Sales_Table[[#This Row],[Discount %]] -> 0 | Q11: =Sales_Table[[#This Row],[Gross Sales]]-Sales_Table[[#This Row],[Discount]] -> 60000 | R11: =VLOOKUP(Sales_Table[[#This Row],[Product ID]],Products[],5,FALSE)*Sales_Table[[#This Row],[Quantity]] -> 36000 | S11: =Sales_Table[[#This Row],[Net Sale]]-Sales_Table[[#This Row],[Total Cost]] -> 24000 | T11: =Sales_Table[[#This Row],[Profit]]/Sales_Table[[#This Row],[Net Sale]] -> 0.4 | U11: =TEXT(Sales_Table[[#This Row],[Order Date]],"mmmm-YYYY") -> January-2026 | V11: =YEAR(Sales_Table[[#This Row],[Month]]) -> 2026 | W11: =TEXT(Sales_Table[[#This Row],[Order Date]],"DDDD") -> Sunday | X11: =IF(OR(Sales_Table[[#This Row],[Days ]]=$W$5,Sales_Table[[#This Row],[Days ]]=$W$8),"Weekned","Weekday") -> Weekned | Y11: =IF(Sales_Table[[#This Row],[Order Status]]="Delivered","Y","N") -> Y | Z11: =IF(Sales_Table[[#This Row],[Order Status]]="Returned","Yes","N") -> N
A12: O1011 | B12: 46050 | C12: C001 | D12: P005 | E12: E001 | F12: Bangalore | G12: Delivered | H12: Card | I12: 7 | J12: 35000 | K12: 0.1 | L12: =_xlfn.XLOOKUP(Sales_Table[[#This Row],[Product ID]],Products[Product ID],Products[Product Name],"N",0) -> Printer | M12: =_xlfn.XLOOKUP(Sales_Table[[#This Row],[Employee ID]],Employees[Employee ID],Employees[Employee Name],"N",0) -> Rahul Kumar | N12: =_xlfn.XLOOKUP(Sales_Table[[#This Row],[Customer ID]],Table22[Customer ID],Table22[Customer Name]) -> ABC Technologies | O12: =Sales_Table[[#This Row],[Unit Price]]*Sales_Table[[#This Row],[Quantity]] -> 245000 | P12: =Sales_Table[[#This Row],[Gross Sales]]*Sales_Table[[#This Row],[Discount %]] -> 24500 | Q12: =Sales_Table[[#This Row],[Gross Sales]]-Sales_Table[[#This Row],[Discount]] -> 220500 | R12: =VLOOKUP(Sales_Table[[#This Row],[Product ID]],Products[],5,FALSE)*Sales_Table[[#This Row],[Quantity]] -> 189000 | S12: =Sales_Table[[#This Row],[Net Sale]]-Sales_Table[[#This Row],[Total Cost]] -> 31500 | T12: =Sales_Table[[#This Row],[Profit]]/Sales_Table[[#This Row],[Net Sale]] -> 0.14285714 | U12: =TEXT(Sales_Table[[#This Row],[Order Date]],"mmmm-YYYY") -> January-2026 | V12: =YEAR(Sales_Table[[#This Row],[Month]]) -> 2026 | W12: =TEXT(Sales_Table[[#This Row],[Order Date]],"DDDD") -> Wednesday | X12: =IF(OR(Sales_Table[[#This Row],[Days ]]=$W$5,Sales_Table[[#This Row],[Days ]]=$W$8),"Weekned","Weekday") -> Weekday | Y12: =IF(Sales_Table[[#This Row],[Order Status]]="Delivered","Y","N") -> Y | Z12: =IF(Sales_Table[[#This Row],[Order Status]]="Returned","Yes","N") -> N
A13: O1012 | B13: 46052 | C13: C002 | D13: P006 | E13: E006 | F13: Pune | G13: Delivered | H13: UPI | I13: 15 | J13: 8000 | K13: 0.05 | L13: =_xlfn.XLOOKUP(Sales_Table[[#This Row],[Product ID]],Products[Product ID],Products[Product Name],"N",0) -> Headset | M13: =_xlfn.XLOOKUP(Sales_Table[[#This Row],[Employee ID]],Employees[Employee ID],Employees[Employee Name],"N",0) -> Anjali Singh | N13: =_xlfn.XLOOKUP(Sales_Table[[#This Row],[Customer ID]],Table22[Customer ID],Table22[Customer Name]) -> Sri Lakshmi Traders | O13: =Sales_Table[[#This Row],[Unit Price]]*Sales_Table[[#This Row],[Quantity]] -> 120000 | P13: =Sales_Table[[#This Row],[Gross Sales]]*Sales_Table[[#This Row],[Discount %]] -> 6000 | Q13: =Sales_Table[[#This Row],[Gross Sales]]-Sales_Table[[#This Row],[Discount]] -> 114000 | R13: =VLOOKUP(Sales_Table[[#This Row],[Product ID]],Products[],5,FALSE)*Sales_Table[[#This Row],[Quantity]] -> 78000 | S13: =Sales_Table[[#This Row],[Net Sale]]-Sales_Table[[#This Row],[Total Cost]] -> 36000 | T13: =Sales_Table[[#This Row],[Profit]]/Sales_Table[[#This Row],[Net Sale]] -> 0.31578947 | U13: =TEXT(Sales_Table[[#This Row],[Order Date]],"mmmm-YYYY") -> January-2026 | V13: =YEAR(Sales_Table[[#This Row],[Month]]) -> 2026 | W13: =TEXT(Sales_Table[[#This Row],[Order Date]],"DDDD") -> Friday | X13: =IF(OR(Sales_Table[[#This Row],[Days ]]=$W$5,Sales_Table[[#This Row],[Days ]]=$W$8),"Weekned","Weekday") -> Weekday | Y13: =IF(Sales_Table[[#This Row],[Order Status]]="Delivered","Y","N") -> Y | Z13: =IF(Sales_Table[[#This Row],[Order Status]]="Returned","Yes","N") -> N
... A121: O1120 | B121: 46380 | C121: C010 | D121: P006 | E121: E002 | F121: Chennai | G121: Delivered | H121: UPI | I121: 34 | J121: 8000 | K121: 0.05 | L121: =_xlfn.XLOOKUP(Sales_Table[[#This Row],[Product ID]],Products[Product ID],Products[Product Name],"N",0) -> Headset | M121: =_xlfn.XLOOKUP(Sales_Table[[#This Row],[Employee ID]],Employees[Employee ID],Employees[Employee Name],"N",0) -> Priya Sharma | N121: =_xlfn.XLOOKUP(Sales_Table[[#This Row],[Customer ID]],Table22[Customer ID],Table22[Customer Name]) -> NextGen Solutions | O121: =Sales_Table[[#This Row],[Unit Price]]*Sales_Table[[#This Row],[Quantity]] -> 272000 | P121: =Sales_Table[[#This Row],[Gross Sales]]*Sales_Table[[#This Row],[Discount %]] -> 13600 | Q121: =Sales_Table[[#This Row],[Gross Sales]]-Sales_Table[[#This Row],[Discount]] -> 258400 | R121: =VLOOKUP(Sales_Table[[#This Row],[Product ID]],Products[],5,FALSE)*Sales_Table[[#This Row],[Quantity]] -> 176800 | S121: =Sales_Table[[#This Row],[Net Sale]]-Sales_Table[[#This Row],[Total Cost]] -> 81600 | T121: =Sales_Table[[#This Row],[Profit]]/Sales_Table[[#This Row],[Net Sale]] -> 0.31578947 | U121: =TEXT(Sales_Table[[#This Row],[Order Date]],"mmmm-YYYY") -> December-2026 | V121: =YEAR(Sales_Table[[#This Row],[Month]]) -> 2026 | W121: =TEXT(Sales_Table[[#This Row],[Order Date]],"DDDD") -> Thursday | X121: =IF(OR(Sales_Table[[#This Row],[Days ]]=$W$5,Sales_Table[[#This Row],[Days ]]=$W$8),"Weekned","Weekday") -> Weekday | Y121: =IF(Sales_Table[[#This Row],[Order Status]]="Delivered","Y","N") -> Y | Z121: =IF(Sales_Table[[#This Row],[Order Status]]="Returned","Yes","N") -> N

Sheet Products
A1: Product ID | B1: Product Name | C1: Category | D1: Brand | E1: Standard Cost | F1: Selling Price
A2: P001 | B2: Laptop | C2: Computers | D2: Dell | E2: 39000 | F2: 50000
A3: P002 | B3: Monitor | C3: Displays | D3: LG | E3: 19000 | F3: 25000
A4: P003 | B4: Keyboard | C4: Accessories | D4: Logitech | E4: 3500 | F4: 5000
A5: P004 | B5: Mouse | C5: Accessories | D5: Logitech | E5: 1200 | F5: 2000
A6: P005 | B6: Printer | C6: Printers | D6: HP | E6: 27000 | F6: 35000
A7: P006 | B7: Headset | C7: Accessories | D7: Boat | E7: 5200 | F7: 8000

Sheet Employess
A1: Employee ID | B1: Employee Name | C1: Department | D1: Joining Date
A2: E001 | B2: Rahul Kumar | C2: Sales | D2: 45458
A3: E002 | B3: Priya Sharma | C3: Sales | D3: 45514
A4: E003 | B4: Arjun Reddy | C4: Sales | D4: 45677
A5: E004 | B5: Sneha Patel | C5: Sales | D5: 45721
A6: E005 | B6: Kiran Rao | C6: Sales | D6: 45789
A7: E006 | B7: Anjali Singh | C7: Sales | D7: 45856

Sheet Customers
A1: Customer ID | B1: Customer Name | C1: Customer Type | D1: City | E1: State
A2: C001 | B2: ABC Technologies | C2: Corporate | D2: Hyderabad | E2: Telangana
A3: C002 | B3: Sri Lakshmi Traders | C3: Business | D3: Chennai | E3: Tamil Nadu
A4: C003 | B4: Vertex Solutions | C4: Corporate | D4: Bangalore | E4: Karnataka
A5: C004 | B5: Royal Enterprises | C5: Business | D5: Pune | E5: Maharashtra
A6: C005 | B6: TechNova Pvt Ltd | C6: Corporate | D6: Hyderabad | E6: Telangana
A7: C006 | B7: Metro Computers | C7: Retail | D7: Chennai | E7: Tamil Nadu
A8: C007 | B8: Future Systems | C8: Corporate | D8: Bangalore | E8: Karnataka
A9: C008 | B9: Prime Digital | C9: Business | D9: Pune | E9: Maharashtra
A10: C009 | B10: Smart World | C10: Retail | D10: Hyderabad | E10: Telangana
A11: C010 | B11: NextGen Solutions | C11: Corporate | D11: Chennai | E11: Tamil Nadu

Sheet Targets
A1: Month | B1: Region | C1: Sales Target
A2: 46023 | B2: Hyderabad | C2: 500000
A3: 46023 | B3: Chennai | C3: 500000
A4: 46023 | B4: Bangalore | C4: 450000
A5: 46023 | B5: Pune | C5: 450000
A6: 46054 | B6: Hyderabad | C6: 500000
A7: 46054 | B7: Chennai | C7: 500000
A8: 46054 | B8: Bangalore | C8: 450000
A9: 46054 | B9: Pune | C9: 450000
A10: 46082 | B10: Hyderabad | C10: 550000
A11: 46082 | B11: Chennai | C11: 550000
A12: 46082 | B12: Bangalore | C12: 500000
A13: 46082 | B13: Pune | C13: 500000
... A37: 46266 | B37: Pune | C37: 650000

Sheet Returns
A1: Return ID | B1: Order ID | C1: Return Date | D1: Return Qty | E1: Return Reason
A2: R001 | B2: O1008 | C2: 46078 | D2: 2 | E2: Damaged
A3: R002 | B3: O1015 | C3: 46093 | D3: 3 | E3: Wrong Product
A4: R003 | B4: O1022 | C4: 46101 | D4: 5 | E4: Customer Cancellation
A5: R004 | B5: O1031 | C5: 46130 | D5: 1 | E5: Damaged
A6: R005 | B6: O1040 | C6: 46162 | D6: 4 | E6: Defective
A7: R006 | B7: O1055 | C7: 46223 | D7: 2 | E7: Wrong Product

Sheet Analysis
A2: KPI Analaysis | D2: Region Analaysis | I2: Product Analaysis | O2: Employee Analaysis | U2: Month Analaysis | AC2: Target Analaysis | AI2: Returned Orders Analaysis
A3: KPI | B3: Value | D3: Region | E3: Net Sales | F3: Profit | G3: Profit % | I3: Product ID | J3: Product Name | K3: Net Sales | L3: Profit | M3: Quantity Sold | O3: Employee ID | P3: Employee Name | Q3: Net Sales | R3: Profit | S3: Orders | U3: Month | V3: Net Sales | W3: Profit | X3: Quantity | Y3: Orders | Z3: Growth % | AC3: Region | AD3: Target | AE3: Actual Sales | AF3: Variance | AG3: Achievement % | AI3: Metric | AJ3: Value | AM3: Q1 | AN3: Which region generated the highest Net Sales? | AO3: Answers
A4: Total Orders | B4: =COUNTA(Sales_Table[Order ID]) -> 120 | D4: Hyderabad | E4: =SUMIF(Sales_Table[Region],'Sales Raw Data'!F104,Sales_Table[Net Sale]) -> 7549900 | F4: =SUMIF(Sales_Table[Region],'Sales Raw Data'!F62,Sales_Table[Profit]) -> 1222400 | G4: =IFERROR(F4/E4,0) -> 0.16190943 | I4: P001 | J4: =VLOOKUP(I4,Products[],2,FALSE) -> Laptop | K4: =SUMIFS(Sales_Table[Net Sale],Sales_Table[Product Name],J4,Sales_Table[Order Status],Sales_Table[[#This Row],[Order Status]]) -> 5139000 | L4: =SUMIFS(Sales_Table[Profit],Sales_Table[Sale Eligilblity],Sales_Table[[#This Row],[Sale Eligilblity]],Sales_Table[Product ID],Sales_Table[[#This Row],[Product ID]]) -> 770200 | M4: =SUMIFS(Sales_Table[Quantity],Sales_Table[Product ID],Sales_Table[[#This Row],[Product ID]],Sales_Table[Sale Eligilblity],Sales_Table[[#This Row],[Sale Eligilblity]]) -> 632 | O4: E001 | P4: =VLOOKUP(O4,Employees[],MATCH(Employees[[#Headers],[Employee Name]],Employees[#Headers],0),FALSE) -> Rahul Kumar | Q4: =SUMIFS(Sales_Table[Net Sale],Sales_Table[Employee ID],Analysis!O4,Sales_Table[Sale Eligilblity],Sales_Table[[#This Row],[Sale Eligilblity]]) -> 5858500 | R4: =SUMIFS(Sales_Table[Profit],Sales_Table[Employee ID],Analysis!O4,Sales_Table[Sale Eligilblity],Sales_Table[[#This Row],[Sale Eligilblity]]) -> 857500 | S4: =COUNTIFS(Sales_Table[Employee ID],Analysis!O4,Sales_Table[Sale Eligilblity],Sales_Table[[#This Row],[Sale Eligilblity]]) -> 20 | U4: =AE12 -> Jan-26 | V4: =AF12 -> 1726400 | W4: =AG12 -> 342000 | X4: =AH12 -> 157 | Y4: =AI12 -> 12 | Z4: =AJ12 -> 0 | AC4: Hyderabad | AD4: =SUMIF(Targets!B2:B37,Analysis!AC4,Targets!C2:C37) -> 5150000 | AE4: =SUMIFS(Sales_Table[Net Sale],Sales_Table[Sale Eligilblity],Sales_Table[[#This Row],[Sale Eligilblity]],Sales_Table[Region],Analysis!AC4) -> 7549900 | AF4: =AE4-AD4 -> 2399900 | AG4: =AF4/AD4 -> 0.466 | AI4: Total Returned Orders | AJ4: =COUNTIF(Sales_Table[Order Status],"Returned") -> 2 | AO4: =_xlfn.XLOOKUP(MAX(E4:E7),E4:E7,D4:D7) -> Hyderabad
A5: Delivered Orders | B5: =COUNTIF(Sales_Table[Order Status],'Sales Raw Data'!G2) -> 117 | D5: Chennai | E5: =SUMIF(Sales_Table[Region],'Sales Raw Data'!F105,Sales_Table[Net Sale]) -> 6887500 | F5: =SUMIF(Sales_Table[Region],'Sales Raw Data'!F63,Sales_Table[Profit]) -> 1471100 | G5: =IFERROR(F5/E5,0) -> 0.21358984 | I5: P002 | J5: =VLOOKUP(I5,Products[],2,FALSE) -> Monitor | K5: =SUMIFS(Sales_Table[Net Sale],Sales_Table[Product Name],J5,Sales_Table[Order Status],Sales_Table[[#This Row],[Order Status]]) -> 6904000 | L5: =SUMIFS(Sales_Table[Profit],Sales_Table[Sale Eligilblity],Sales_Table[[#This Row],[Sale Eligilblity]],Sales_Table[Product ID],Sales_Table[[#This Row],[Product ID]]) -> 666400 | M5: =SUMIFS(Sales_Table[Quantity],Sales_Table[Product ID],Sales_Table[[#This Row],[Product ID]],Sales_Table[Sale Eligilblity],Sales_Table[[#This Row],[Sale Eligilblity]]) -> 833 | O5: E002 | P5: =VLOOKUP(O5,Employees[],MATCH(Employees[[#Headers],[Employee Name]],Employees[#Headers],0),FALSE) -> Priya Sharma | Q5: =SUMIFS(Sales_Table[Net Sale],Sales_Table[Employee ID],Analysis!O5,Sales_Table[Sale Eligilblity],Sales_Table[[#This Row],[Sale Eligilblity]]) -> 3637840 | R5: =SUMIFS(Sales_Table[Profit],Sales_Table[Employee ID],Analysis!O5,Sales_Table[Sale Eligilblity],Sales_Table[[#This Row],[Sale Eligilblity]]) -> 1031440 | S5: =COUNTIFS(Sales_Table[Employee ID],Analysis!O5,Sales_Table[Sale Eligilblity],Sales_Table[[#This Row],[Sale Eligilblity]]) -> 20 | U5: =AE13 -> Feb-26 | V5: =AF13 -> 1249000 | W5: =AG13 -> 230000 | X5: =AH13 -> 80 | Y5: =AI13 -> 7 | Z5: =AJ13 -> -0.27652919 | AC5: Chennai | AD5: =SUMIF(Targets!B3:B38,Analysis!AC5,Targets!C3:C38) -> 5150000 | AE5: =SUMIFS(Sales_Table[Net Sale],Sales_Table[Sale Eligilblity],Sales_Table[[#This Row],[Sale Eligilblity]],Sales_Table[Region],Analysis!AC5) -> 6817500 | AF5: =AE5-AD5 -> 1667500 | AG5: =AF5/AD5 -> 0.32378641 | AI5: Returned Quantity | AJ5: =SUMIF(Sales_Table[Order Status],"Returned",Sales_Table[Quantity]) -> 23
A6: Cancelled Orders | B6: =COUNTIF(Sales_Table[Order Status],'Sales Raw Data'!$G$23) -> 1 | D6: Bangalore | E6: =SUMIF(Sales_Table[Region],'Sales Raw Data'!F106,Sales_Table[Net Sale]) -> 6589000 | F6: =SUMIF(Sales_Table[Region],'Sales Raw Data'!F64,Sales_Table[Profit]) -> 1123500 | G6: =IFERROR(F6/E6,0) -> 0.17051146 | I6: P003 | J6: =VLOOKUP(I6,Products[],2,FALSE) -> Keyboard | K6: =SUMIFS(Sales_Table[Net Sale],Sales_Table[Product Name],J6,Sales_Table[Order Status],Sales_Table[[#This Row],[Order Status]]) -> 2982200 | L6: =SUMIFS(Sales_Table[Profit],Sales_Table[Sale Eligilblity],Sales_Table[[#This Row],[Sale Eligilblity]],Sales_Table[Product ID],Sales_Table[[#This Row],[Product ID]]) -> 846200 | M6: =SUMIFS(Sales_Table[Quantity],Sales_Table[Product ID],Sales_Table[[#This Row],[Product ID]],Sales_Table[Sale Eligilblity],Sales_Table[[#This Row],[Sale Eligilblity]]) -> 184 | O6: E003 | P6: =VLOOKUP(O6,Employees[],MATCH(Employees[[#Headers],[Employee Name]],Employees[#Headers],0),FALSE) -> Arjun Reddy | Q6: =SUMIFS(Sales_Table[Net Sale],Sales_Table[Employee ID],Analysis!O6,Sales_Table[Sale Eligilblity],Sales_Table[[#This Row],[Sale Eligilblity]]) -> 4900750 | R6: =SUMIFS(Sales_Table[Profit],Sales_Table[Employee ID],Analysis!O6,Sales_Table[Sale Eligilblity],Sales_Table[[#This Row],[Sale Eligilblity]]) -> 654250 | S6: =COUNTIFS(Sales_Table[Employee ID],Analysis!O6,Sales_Table[Sale Eligilblity],Sales_Table[[#This Row],[Sale Eligilblity]]) -> 19 | U6: =AE14 -> Mar-26 | V6: =AF14 -> 1318000 | W6: =AG14 -> 239400 | X6: =AH14 -> 139 | Y6: =AI14 -> 7 | Z6: =AJ14 -> 0.055244195 | AC6: Bangalore | AD6: =SUMIF(Targets!B4:B39,Analysis!AC6,Targets!C4:C39) -> 4700000 | AE6: =SUMIFS(Sales_Table[Net Sale],Sales_Table[Sale Eligilblity],Sales_Table[[#This Row],[Sale Eligilblity]],Sales_Table[Region],Analysis!AC6) -> 6273500 | AF6: =AE6-AD6 -> 1573500 | AG6: =AF6/AD6 -> 0.33478723 | AI6: Return Value | AJ6: =SUMIF(Sales_Table[Order Status],"Returned",Sales_Table[Net Sale]) -> 315500 | AM6: Q2 | AN6: Which product sold the highest quantity? | AO6: =_xlfn.XLOOKUP(MAX(M4:M9),M4:M9,J4:J9) -> Monitor
A7: Returned Orders | B7: =COUNTIF(Sales_Table[Order Status],'Sales Raw Data'!$G$16) -> 2 | D7: Pune | E7: =SUMIF(Sales_Table[Region],'Sales Raw Data'!F107,Sales_Table[Net Sale]) -> 5235540 | F7: =SUMIF(Sales_Table[Region],'Sales Raw Data'!F65,Sales_Table[Profit]) -> 1243540 | G7: =IFERROR(F7/E7,0) -> 0.23751896 | I7: P004 | J7: =VLOOKUP(I7,Products[],2,FALSE) -> Mouse | K7: =SUMIFS(Sales_Table[Net Sale],Sales_Table[Product Name],J7,Sales_Table[Order Status],Sales_Table[[#This Row],[Order Status]]) -> 1666000 | L7: =SUMIFS(Sales_Table[Profit],Sales_Table[Sale Eligilblity],Sales_Table[[#This Row],[Sale Eligilblity]],Sales_Table[Product ID],Sales_Table[[#This Row],[Product ID]]) -> 1062240 | M7: =SUMIFS(Sales_Table[Quantity],Sales_Table[Product ID],Sales_Table[[#This Row],[Product ID]],Sales_Table[Sale Eligilblity],Sales_Table[[#This Row],[Sale Eligilblity]]) -> 444 | O7: E004 | P7: =VLOOKUP(O7,Employees[],MATCH(Employees[[#Headers],[Employee Name]],Employees[#Headers],0),FALSE) -> Sneha Patel | Q7: =SUMIFS(Sales_Table[Net Sale],Sales_Table[Employee ID],Analysis!O7,Sales_Table[Sale Eligilblity],Sales_Table[[#This Row],[Sale Eligilblity]]) -> 6662750 | R7: =SUMIFS(Sales_Table[Profit],Sales_Table[Employee ID],Analysis!O7,Sales_Table[Sale Eligilblity],Sales_Table[[#This Row],[Sale Eligilblity]]) -> 965250 | S7: =COUNTIFS(Sales_Table[Employee ID],Analysis!O7,Sales_Table[Sale Eligilblity],Sales_Table[[#This Row],[Sale Eligilblity]]) -> 20 | U7: =AE15 -> Apr-26 | V7: =AF15 -> 1367440 | W7: =AG15 -> 266040 | X7: =AH15 -> 121 | Y7: =AI15 -> 8 | Z7: =AJ15 -> 0.037511381 | AC7: Pune | AD7: =SUMIF(Targets!B5:B40,Analysis!AC7,Targets!C5:C40) -> 4700000 | AE7: =SUMIFS(Sales_Table[Net Sale],Sales_Table[Sale Eligilblity],Sales_Table[[#This Row],[Sale Eligilblity]],Sales_Table[Region],Analysis!AC7) -> 5235540 | AF7: =AE7-AD7 -> 535540 | AG7: =AF7/AD7 -> 0.11394468 | AI7: Return Rate | AJ7: =AJ4/B4 -> 0.016666667 | AM7: Q3 | AN7: Which product generated the highest profit? | AO7: =_xlfn.XLOOKUP(MAX(L4:L9),L4:L9,J4:J9) -> Mouse
A8: Total Quantity Sold | B8: =SUMIFS(Sales_Table[Quantity],Sales_Table[Sale Eligilblity],'Sales Raw Data'!Y103) -> 2520 | I8: P005 | J8: =VLOOKUP(I8,Products[],2,FALSE) -> Printer | K8: =SUMIFS(Sales_Table[Net Sale],Sales_Table[Product Name],J8,Sales_Table[Order Status],Sales_Table[[#This Row],[Order Status]]) -> 5814200 | L8: =SUMIFS(Sales_Table[Profit],Sales_Table[Sale Eligilblity],Sales_Table[[#This Row],[Sale Eligilblity]],Sales_Table[Product ID],Sales_Table[[#This Row],[Product ID]]) -> 654000 | M8: =SUMIFS(Sales_Table[Quantity],Sales_Table[Product ID],Sales_Table[[#This Row],[Product ID]],Sales_Table[Sale Eligilblity],Sales_Table[[#This Row],[Sale Eligilblity]]) -> 115 | O8: E005 | P8: =VLOOKUP(O8,Employees[],MATCH(Employees[[#Headers],[Employee Name]],Employees[#Headers],0),FALSE) -> Kiran Rao | Q8: =SUMIFS(Sales_Table[Net Sale],Sales_Table[Employee ID],Analysis!O8,Sales_Table[Sale Eligilblity],Sales_Table[[#This Row],[Sale Eligilblity]]) -> 3045400 | R8: =SUMIFS(Sales_Table[Profit],Sales_Table[Employee ID],Analysis!O8,Sales_Table[Sale Eligilblity],Sales_Table[[#This Row],[Sale Eligilblity]]) -> 775400 | S8: =COUNTIFS(Sales_Table[Employee ID],Analysis!O8,Sales_Table[Sale Eligilblity],Sales_Table[[#This Row],[Sale Eligilblity]]) -> 19 | U8: =AE16 -> May-26 | V8: =AF16 -> 0 | W8: =AG16 -> 0 | X8: =AH16 -> 0 | Y8: =AI16 -> 0 | Z8: =AJ16 -> -1 | AM8: Q4 | AN8: Which employee generated the highest sales? | AO8: =_xlfn.XLOOKUP(MAX(Q4:Q9),Q4:Q9,P4:P9) -> Sneha Patel
A9: Total Net Sales | B9: =SUMIF(Sales_Table[Sale Eligilblity],'Sales Raw Data'!Y103,Sales_Table[Net Sale]) -> 25876440 | I9: P006 | J9: =VLOOKUP(I9,Products[],2,FALSE) -> Headset | K9: =SUMIFS(Sales_Table[Net Sale],Sales_Table[Product Name],J9,Sales_Table[Order Status],Sales_Table[[#This Row],[Order Status]]) -> 3371040 | L9: =SUMIFS(Sales_Table[Profit],Sales_Table[Sale Eligilblity],Sales_Table[[#This Row],[Sale Eligilblity]],Sales_Table[Product ID],Sales_Table[[#This Row],[Product ID]]) -> 976000 | M9: =SUMIFS(Sales_Table[Quantity],Sales_Table[Product ID],Sales_Table[[#This Row],[Product ID]],Sales_Table[Sale Eligilblity],Sales_Table[[#This Row],[Sale Eligilblity]]) -> 312 | O9: E006 | P9: =VLOOKUP(O9,Employees[],MATCH(Employees[[#Headers],[Employee Name]],Employees[#Headers],0),FALSE) -> Anjali Singh | Q9: =SUMIFS(Sales_Table[Net Sale],Sales_Table[Employee ID],Analysis!O9,Sales_Table[Sale Eligilblity],Sales_Table[[#This Row],[Sale Eligilblity]]) -> 1771200 | R9: =SUMIFS(Sales_Table[Profit],Sales_Table[Employee ID],Analysis!O9,Sales_Table[Sale Eligilblity],Sales_Table[[#This Row],[Sale Eligilblity]]) -> 691200 | S9: =COUNTIFS(Sales_Table[Employee ID],Analysis!O9,Sales_Table[Sale Eligilblity],Sales_Table[[#This Row],[Sale Eligilblity]]) -> 19 | U9: =AE17 -> Jun-26 | V9: =AF17 -> 1562500 | W9: =AG17 -> 327000 | X9: =AH17 -> 197 | Y9: =AI17 -> 8 | Z9: =AJ17 -> 0 | AM9: Q5 | AN9: Which region has the highest Profit %? | AO9: =_xlfn.XLOOKUP(MAX(G4:G7),G4:G7,D4:D7) -> Pune | AQ9: Q6
A10: Total Cost | B10: =SUMIF(Sales_Table[Sale Eligilblity],'Sales Raw Data'!Y106,Sales_Table[Total Cost]) -> 20901400 | U10: =AE18 -> Jul-26 | V10: =AF18 -> 1387100 | W10: =AG18 -> 288900 | X10: =AH18 -> 144 | Y10: =AI18 -> 7 | Z10: =AJ18 -> -0.112256 | AM10: Q6 | AN10: Find orders with high sales but low profit % | AO10: =AVERAGEIF(Sales_Table[Order Status],'Sales Raw Data'!G107,Sales_Table[Net Sale]) -> 221166.15 | AP10: =AVERAGEIF(Sales_Table[Order Status],'Sales Raw Data'!G2,Sales_Table[profit%]) -> 0.2309187 | AQ10: {=_xlfn._xlws.FILTER(Sales_Table[Order ID],(Sales_Table[Net Sale]>Analysis!AO10)*(Sales_Table[profit%]<Analysis!AP10))} -> O1001
A11: Total Profit | B11: =SUMIF(Sales_Table[Sale Eligilblity],'Sales Raw Data'!Y107,Sales_Table[Profit]) -> 4975040 | U11: =AE19 -> Aug-26 | V11: =AF19 -> 1927950 | W11: =AG19 -> 329750 | X11: =AH19 -> 152 | Y11: =AI19 -> 8 | Z11: =AJ19 -> 0.38991421 | AE11: Month | AF11: Net Sales | AG11: Profit | AH11: Quantity | AI11: Orders | AJ11: Growth % | AM11: Q7 | AN11: Find the highest Net Sale order | AO11: =_xlfn.XLOOKUP(MAX(Sales_Table[Net Sale]),Sales_Table[Net Sale],Sales_Table[Order ID]) -> O1116 | AQ11: O1014
A12: Overall Profit % | B12: =B11/B9 -> 0.19226138 | U12: =AE20 -> Sep-26 | V12: =AF20 -> 3655200 | W12: =AG20 -> 721700 | X12: =AH20 -> 410 | Y12: =AI20 -> 16 | Z12: =AJ20 -> 0.89589979 | AE12: {=TEXT(_xlfn.UNIQUE(Sales_Table[Month],FALSE),"MMM-YY")} -> Jan-26 | AF12: =SUMIFS(Sales_Table[Net Sale],Sales_Table[Sale Eligilblity],Sales_Table[[#This Row],[Sale Eligilblity]],Sales_Table[Month],Analysis!AE12) -> 1726400 | AG12: =SUMIFS(Sales_Table[Profit],Sales_Table[Sale Eligilblity],Sales_Table[[#This Row],[Sale Eligilblity]],Sales_Table[Month],Analysis!AE12) -> 342000 | AH12: =SUMIFS(Sales_Table[Quantity],Sales_Table[Month],Analysis!AE12,Sales_Table[Sale Eligilblity],Sales_Table[[#This Row],[Sale Eligilblity]]) -> 157 | AI12: =COUNTIFS(Sales_Table[Sale Eligilblity],Sales_Table[[#This Row],[Sale Eligilblity]],Sales_Table[Month],Analysis!AE12) -> 12 | AM12: Q8 | AN12: Find sales for Chennai + P001 | AO12: =SUMIFS(Sales_Table[Net Sale],Sales_Table[Product ID],'Sales Raw Data'!D2,Sales_Table[Region],'Sales Raw Data'!F3) -> 264000 | AP12: Q9 | AQ12: O1018
U13: =AE21 -> Oct-26 | V13: =AF21 -> 3064600 | W13: =AG21 -> 601400 | X13: =AH21 -> 299 | Y13: =AI21 -> 12 | Z13: =AJ21 -> -0.16157803 | AE13: Feb-26 | AF13: =SUMIFS(Sales_Table[Net Sale],Sales_Table[Sale Eligilblity],Sales_Table[[#This Row],[Sale Eligilblity]],Sales_Table[Month],Analysis!AE13) -> 1249000 | AG13: =SUMIFS(Sales_Table[Profit],Sales_Table[Sale Eligilblity],Sales_Table[[#This Row],[Sale Eligilblity]],Sales_Table[Month],Analysis!AE13) -> 230000 | AH13: =SUMIFS(Sales_Table[Quantity],Sales_Table[Month],Analysis!AE13,Sales_Table[Sale Eligilblity],Sales_Table[[#This Row],[Sale Eligilblity]]) -> 80 | AI13: =COUNTIFS(Sales_Table[Sale Eligilblity],Sales_Table[[#This Row],[Sale Eligilblity]],Sales_Table[Month],Analysis!AE13) -> 7 | AJ13: =IFERROR(AF13/AF12-1,0) -> -0.27652919 | AM13: Q9 | AN13: Find delivered orders only | AP13: {=_xlfn._xlws.FILTER(Sales_Table[Order ID],Sales_Table[Order Status]='Sales Raw Data'!G2)} -> O1001 | AQ13: O1023
U14: =AE22 -> Nov-26 | V14: =AF22 -> 3266550 | W14: =AG22 -> 620450 | X14: =AH22 -> 330 | Y14: =AI22 -> 12 | Z14: =AJ22 -> 0.06589767 | AE14: Mar-26 | AF14: =SUMIFS(Sales_Table[Net Sale],Sales_Table[Sale Eligilblity],Sales_Table[[#This Row],[Sale Eligilblity]],Sales_Table[Month],Analysis!AE14) -> 1318000 | AG14: =SUMIFS(Sales_Table[Profit],Sales_Table[Sale Eligilblity],Sales_Table[[#This Row],[Sale Eligilblity]],Sales_Table[Month],Analysis!AE14) -> 239400 | AH14: =SUMIFS(Sales_Table[Quantity],Sales_Table[Month],Analysis!AE14,Sales_Table[Sale Eligilblity],Sales_Table[[#This Row],[Sale Eligilblity]]) -> 139 | AI14: =COUNTIFS(Sales_Table[Sale Eligilblity],Sales_Table[[#This Row],[Sale Eligilblity]],Sales_Table[Month],Analysis!AE14) -> 7 | AJ14: =IFERROR(AF14/AF13-1,0) -> 0.055244195 | AM14: Q10 | AN14: Find cancelled orders | AO14: {=_xlfn._xlws.FILTER(Sales_Table[Order ID],Sales_Table[Order Status]='Sales Raw Data'!G23)} -> O1022 | AP14: O1002 | AQ14: O1025
U15: =AE23 -> Dec-26 | V15: =AF23 -> 0 | W15: =AG23 -> 0 | X15: =AH23 -> 0 | Y15: =AI23 -> 0 | Z15: =AJ23 -> -1 | AE15: Apr-26 | AF15: =SUMIFS(Sales_Table[Net Sale],Sales_Table[Sale Eligilblity],Sales_Table[[#This Row],[Sale Eligilblity]],Sales_Table[Month],Analysis!AE15) -> 1367440 | AG15: =SUMIFS(Sales_Table[Profit],Sales_Table[Sale Eligilblity],Sales_Table[[#This Row],[Sale Eligilblity]],Sales_Table[Month],Analysis!AE15) -> 266040 | AH15: =SUMIFS(Sales_Table[Quantity],Sales_Table[Month],Analysis!AE15,Sales_Table[Sale Eligilblity],Sales_Table[[#This Row],[Sale Eligilblity]]) -> 121 | AI15: =COUNTIFS(Sales_Table[Sale Eligilblity],Sales_Table[[#This Row],[Sale Eligilblity]],Sales_Table[Month],Analysis!AE15) -> 8 | AJ15: =IFERROR(AF15/AF14-1,0) -> 0.037511381 | AP15: O1003 | AQ15: O1026
AE16: May-26 | AF16: =SUMIFS(Sales_Table[Net Sale],Sales_Table[Sale Eligilblity],Sales_Table[[#This Row],[Sale Eligilblity]],Sales_Table[Month],Analysis!AE16) -> 0 | AG16: =SUMIFS(Sales_Table[Profit],Sales_Table[Sale Eligilblity],Sales_Table[[#This Row],[Sale Eligilblity]],Sales_Table[Month],Analysis!AE16) -> 0 | AH16: =SUMIFS(Sales_Table[Quantity],Sales_Table[Month],Analysis!AE16,Sales_Table[Sale Eligilblity],Sales_Table[[#This Row],[Sale Eligilblity]]) -> 0 | AI16: =COUNTIFS(Sales_Table[Sale Eligilblity],Sales_Table[[#This Row],[Sale Eligilblity]],Sales_Table[Month],Analysis!AE16) -> 0 | AJ16: =IFERROR(AF16/AF15-1,0) -> -1 | AP16: O1004 | AQ16: O1029
AE17: Jun-26 | AF17: =SUMIFS(Sales_Table[Net Sale],Sales_Table[Sale Eligilblity],Sales_Table[[#This Row],[Sale Eligilblity]],Sales_Table[Month],Analysis!AE17) -> 1562500 | AG17: =SUMIFS(Sales_Table[Profit],Sales_Table[Sale Eligilblity],Sales_Table[[#This Row],[Sale Eligilblity]],Sales_Table[Month],Analysis!AE17) -> 327000 | AH17: =SUMIFS(Sales_Table[Quantity],Sales_Table[Month],Analysis!AE17,Sales_Table[Sale Eligilblity],Sales_Table[[#This Row],[Sale Eligilblity]]) -> 197 | AI17: =COUNTIFS(Sales_Table[Sale Eligilblity],Sales_Table[[#This Row],[Sale Eligilblity]],Sales_Table[Month],Analysis!AE17) -> 8 | AJ17: =IFERROR(AF17/AF16-1,0) -> 0 | AP17: O1005 | AQ17: O1031
AE18: Jul-26 | AF18: =SUMIFS(Sales_Table[Net Sale],Sales_Table[Sale Eligilblity],Sales_Table[[#This Row],[Sale Eligilblity]],Sales_Table[Month],Analysis!AE18) -> 1387100 | AG18: =SUMIFS(Sales_Table[Profit],Sales_Table[Sale Eligilblity],Sales_Table[[#This Row],[Sale Eligilblity]],Sales_Table[Month],Analysis!AE18) -> 288900 | AH18: =SUMIFS(Sales_Table[Quantity],Sales_Table[Month],Analysis!AE18,Sales_Table[Sale Eligilblity],Sales_Table[[#This Row],[Sale Eligilblity]]) -> 144 | AI18: =COUNTIFS(Sales_Table[Sale Eligilblity],Sales_Table[[#This Row],[Sale Eligilblity]],Sales_Table[Month],Analysis!AE18) -> 7 | AJ18: =IFERROR(AF18/AF17-1,0) -> -0.112256 | AP18: O1006 | AQ18: O1032
AE19: Aug-26 | AF19: =SUMIFS(Sales_Table[Net Sale],Sales_Table[Sale Eligilblity],Sales_Table[[#This Row],[Sale Eligilblity]],Sales_Table[Month],Analysis!AE19) -> 1927950 | AG19: =SUMIFS(Sales_Table[Profit],Sales_Table[Sale Eligilblity],Sales_Table[[#This Row],[Sale Eligilblity]],Sales_Table[Month],Analysis!AE19) -> 329750 | AH19: =SUMIFS(Sales_Table[Quantity],Sales_Table[Month],Analysis!AE19,Sales_Table[Sale Eligilblity],Sales_Table[[#This Row],[Sale Eligilblity]]) -> 152 | AI19: =COUNTIFS(Sales_Table[Sale Eligilblity],Sales_Table[[#This Row],[Sale Eligilblity]],Sales_Table[Month],Analysis!AE19) -> 8 | AJ19: =IFERROR(AF19/AF18-1,0) -> 0.38991421 | AP19: O1007 | AQ19: O1037
AE20: Sep-26 | AF20: =SUMIFS(Sales_Table[Net Sale],Sales_Table[Sale Eligilblity],Sales_Table[[#This Row],[Sale Eligilblity]],Sales_Table[Month],Analysis!AE20) -> 3655200 | AG20: =SUMIFS(Sales_Table[Profit],Sales_Table[Sale Eligilblity],Sales_Table[[#This Row],[Sale Eligilblity]],Sales_Table[Month],Analysis!AE20) -> 721700 | AH20: =SUMIFS(Sales_Table[Quantity],Sales_Table[Month],Analysis!AE20,Sales_Table[Sale Eligilblity],Sales_Table[[#This Row],[Sale Eligilblity]]) -> 410 | AI20: =COUNTIFS(Sales_Table[Sale Eligilblity],Sales_Table[[#This Row],[Sale Eligilblity]],Sales_Table[Month],Analysis!AE20) -> 16 | AJ20: =IFERROR(AF20/AF19-1,0) -> 0.89589979 | AP20: O1008 | AQ20: O1038
AE21: Oct-26 | AF21: =SUMIFS(Sales_Table[Net Sale],Sales_Table[Sale Eligilblity],Sales_Table[[#This Row],[Sale Eligilblity]],Sales_Table[Month],Analysis!AE21) -> 3064600 | AG21: =SUMIFS(Sales_Table[Profit],Sales_Table[Sale Eligilblity],Sales_Table[[#This Row],[Sale Eligilblity]],Sales_Table[Month],Analysis!AE21) -> 601400 | AH21: =SUMIFS(Sales_Table[Quantity],Sales_Table[Month],Analysis!AE21,Sales_Table[Sale Eligilblity],Sales_Table[[#This Row],[Sale Eligilblity]]) -> 299 | AI21: =COUNTIFS(Sales_Table[Sale Eligilblity],Sales_Table[[#This Row],[Sale Eligilblity]],Sales_Table[Month],Analysis!AE21) -> 12 | AJ21: =IFERROR(AF21/AF20-1,0) -> -0.16157803 | AP21: O1009 | AQ21: O1041
AE22: Nov-26 | AF22: =SUMIFS(Sales_Table[Net Sale],Sales_Table[Sale Eligilblity],Sales_Table[[#This Row],[Sale Eligilblity]],Sales_Table[Month],Analysis!AE22) -> 3266550 | AG22: =SUMIFS(Sales_Table[Profit],Sales_Table[Sale Eligilblity],Sales_Table[[#This Row],[Sale Eligilblity]],Sales_Table[Month],Analysis!AE22) -> 620450 | AH22: =SUMIFS(Sales_Table[Quantity],Sales_Table[Month],Analysis!AE22,Sales_Table[Sale Eligilblity],Sales_Table[[#This Row],[Sale Eligilblity]]) -> 330 | AI22: =COUNTIFS(Sales_Table[Sale Eligilblity],Sales_Table[[#This Row],[Sale Eligilblity]],Sales_Table[Month],Analysis!AE22) -> 12 | AJ22: =IFERROR(AF22/AF21-1,0) -> 0.06589767 | AP22: O1010 | AQ22: O1044
AE23: Dec-26 | AF23: =SUMIFS(Sales_Table[Net Sale],Sales_Table[Sale Eligilblity],Sales_Table[[#This Row],[Sale Eligilblity]],Sales_Table[Month],Analysis!AE23) -> 0 | AG23: =SUMIFS(Sales_Table[Profit],Sales_Table[Sale Eligilblity],Sales_Table[[#This Row],[Sale Eligilblity]],Sales_Table[Month],Analysis!AE23) -> 0 | AH23: =SUMIFS(Sales_Table[Quantity],Sales_Table[Month],Analysis!AE23,Sales_Table[Sale Eligilblity],Sales_Table[[#This Row],[Sale Eligilblity]]) -> 0 | AI23: =COUNTIFS(Sales_Table[Sale Eligilblity],Sales_Table[[#This Row],[Sale Eligilblity]],Sales_Table[Month],Analysis!AE23) -> 0 | AJ23: =IFERROR(AF23/AF22-1,0) -> -1 | AP23: O1011 | AQ23: O1047
AP24: O1012 | AQ24: O1049
AP25: O1013 | AQ25: O1050
AP26: O1014 | AQ26: O1053
AP27: O1016 | AQ27: O1055
AP28: O1017 | AQ28: O1056
AP29: O1018 | AQ29: O1059
AP30: O1019 | AQ30: O1061
AP31: O1020 | AQ31: O1062
AP32: O1021 | AQ32: O1065
AP33: O1023 | AQ33: O1067
AP34: O1024 | AQ34: O1068
AP35: O1025 | AQ35: O1071
... AP58: O1048 | AQ58: O1119
AP59: O1049
AP60: O1050
AP61: O1051
AP62: O1052
AP63: O1053
...

Sheet PivotTables
A1: Sale Eligilblity | B1: Y
A2: Region Performance | F2: Product Performance
A3: Row Labels | B3: Sum of Quantity | C3: Sum of Net Sale | D3: Sum of Profit | F3: Row Labels | G3: Sum of Quantity | H3: Sum of Net Sale | I3: Sum of Profit
A4: Bangalore | B4: 458 | C4: 6273500 | D4: 1066000 | F4: Headset | G4: 444 | H4: 3371040 | I4: 1062240
A5: Chennai | B5: 764 | C5: 6817500 | D5: 1443100 | F5: Keyboard | G5: 650 | H5: 3067700 | I5: 792700
A6: Hyderabad | B6: 487 | C6: 7549900 | D6: 1222400 | F6: Laptop | G6: 120 | H6: 5369000 | I6: 689000
A7: Pune | B7: 811 | C7: 5235540 | D7: 1243540 | F7: Monitor | G7: 312 | H7: 6904000 | I7: 976000
A8: Grand Total | B8: 2520 | C8: 25876440 | D8: 4975040 | F8: Mouse | G8: 868 | H8: 1736000 | I8: 694400
F9: Printer | G9: 184 | H9: 5814200 | I9: 846200
F10: Grand Total | G10: 2578 | H10: 26261940 | I10: 5060540
A11: Employee Performance
A12: Row Labels | B12: Sum of Net Sale | C12: Sum of Profit
A13: Anjali Singh | B13: 1841200 | C13: 719200
A14: Arjun Reddy | B14: 5130750 | C14: 689250 | F14: Monthly Sales
A15: Kiran Rao | B15: 3130900 | C15: 797900 | F15: Row Labels | G15: Sum of Profit | H15: Sum of Net Sale
A16: Priya Sharma | B16: 3637840 | C16: 1031440 | F16: Jan | G16: 342000 | H16: 1726400
A17: Rahul Kumar | B17: 5858500 | C17: 857500 | F17: Feb | G17: 252500 | H17: 1334500
A18: Sneha Patel | B18: 6662750 | C18: 965250 | F18: Mar | G18: 267400 | H18: 1388000
A19: Grand Total | B19: 26261940 | C19: 5060540 | F19: Apr | G19: 266040 | H19: 1367440
F20: May | G20: 308100 | H20: 1732200
F21: Jun | G21: 327000 | H21: 1562500
A22: Order Status | F22: Jul | G22: 323900 | H22: 1617100
A23: Row Labels | B23: Count of Order ID | F23: Aug | G23: 329750 | H23: 1927950
A24: Cancelled | B24: 1 | F24: Sep | G24: 721700 | H24: 3655200
A25: Delivered | B25: 117 | F25: Oct | G25: 601400 | H25: 3064600
A26: Returned | B26: 2 | F26: Nov | G26: 620450 | H26: 3266550
A27: Grand Total | B27: 120 | F27: Dec | G27: 700300 | H27: 3619500
F28: Grand Total | G28: 5060540 | H28: 26261940

Sheet Dashboard

Sheet Final Business Insights
B2: Sales Performance
B3: ="Total eligible Net Sales were ₹ "&TEXT(Analysis!B9,"0.00,,") &"M with total profit of ₹"&TEXT(Analysis!B11,"0.00,,")&"M ." -> Total eligible Net Sales were ₹ 25.88M with total profit of ₹4.98M .
B5: Region Performance
B6: ="The region with the highest Net Sales was ₹ "&TEXT(Analysis!E4,"0.00,,")&"M based on the regional analysis " -> The region with the highest Net Sales was ₹ 7.55M based on the regional analysis
B8: Product Performance
B9: ="The product with the highest quantity sold was "&Analysis!AO6&"." -> The product with the highest quantity sold was Monitor.
B11: Profitability
B12: ="Overall Profit % was "&TEXT(Analysis!B12,"0%")&"." -> Overall Profit % was 19%.
B14: Returns
B15: =" There were "&TEXT(Analysis!B7,"0")&" returned orders, representing approximately "&TEXT(Analysis!AJ7,"0%")&" of total orders." -> There were 2 returned orders, representing approximately 2% of total orders.

Sheet Project Documentation
A1: Objective
A2: Tools Used
A3: Microsoft Excel
A4: Excel Tables
A5: XLOOKUP
A6: SUMIFS
A7: COUNTIFS
A8: IFERROR
A9: FILTER
A10: PivotTables
A11: PivotCharts
A12: Slicers
... A35: Dashboard

Sheet Sales Table
A1: Order ID | B1: Order Date | C1: Customer ID | D1: Product ID | E1: Employee ID | F1: Region | G1: Order Status | H1: Payment Mode | I1: Quantity | J1: Unit Price | K1: Discount % | L1: Product Name | M1: Employee Name | N1: Customer Name | O1: Gross Sales | P1: Discount | Q1: Net Sale | R1: Total Cost | S1: Profit | T1: profit% | U1: Month | V1: Year | W1: Days | X1: Weekned/Weekday | Y1: Sale Eligilblity | Z1: Retured
A2: O1001 | B2: 46027 | C2: C001 | D2: P001 | E2: E001 | F2: Hyderabad | G2: Delivered | H2: Online | I2: 5 | J2: 50000 | K2: 0.05 | L2: Laptop | M2: Rahul Kumar | N2: ABC Technologies | O2: 250000 | P2: 12500 | Q2: 237500 | R2: 195000 | S2: 42500 | T2: 0.17894737 | U2: 46023 | V2: 2026 | W2: Monday | X2: Weekday | Y2: Y | Z2: N
A3: O1002 | B3: 46028 | C3: C002 | D3: P002 | E3: E002 | F3: Chennai | G3: Delivered | H3: UPI | I3: 8 | J3: 25000 | K3: 0.1 | L3: Monitor | M3: Priya Sharma | N3: Sri Lakshmi Traders | O3: 200000 | P3: 20000 | Q3: 180000 | R3: 152000 | S3: 28000 | T3: 0.15555556 | U3: 46023 | V3: 2026 | W3: Tuesday | X3: Weekday | Y3: Y | Z3: N
A4: O1003 | B4: 46030 | C4: C003 | D4: P003 | E4: E003 | F4: Bangalore | G4: Delivered | H4: Card | I4: 15 | J4: 5000 | K4: 0.05 | L4: Keyboard | M4: Arjun Reddy | N4: Vertex Solutions | O4: 75000 | P4: 3750 | Q4: 71250 | R4: 52500 | S4: 18750 | T4: 0.26315789 | U4: 46023 | V4: 2026 | W4: Thursday | X4: Weekday | Y4: Y | Z4: N
A5: O1004 | B5: 46032 | C5: C004 | D5: P004 | E5: E004 | F5: Pune | G5: Delivered | H5: Cash | I5: 20 | J5: 2000 | K5: 0 | L5: Mouse | M5: Sneha Patel | N5: Royal Enterprises | O5: 40000 | P5: 0 | Q5: 40000 | R5: 24000 | S5: 16000 | T5: 0.4 | U5: 46023 | V5: 2026 | W5: Saturday | X5: Weekned | Y5: Y | Z5: N
A6: O1005 | B6: 46034 | C6: C005 | D6: P005 | E6: E005 | F6: Hyderabad | G6: Delivered | H6: Online | I6: 6 | J6: 35000 | K6: 0.08 | L6: Printer | M6: Kiran Rao | N6: TechNova Pvt Ltd | O6: 210000 | P6: 16800 | Q6: 193200 | R6: 162000 | S6: 31200 | T6: 0.16149068 | U6: 46023 | V6: 2026 | W6: Monday | X6: Weekday | Y6: Y | Z6: N
A7: O1006 | B7: 46037 | C7: C006 | D7: P006 | E7: E006 | F7: Chennai | G7: Delivered | H7: UPI | I7: 12 | J7: 8000 | K7: 0.05 | L7: Headset | M7: Anjali Singh | N7: Metro Computers | O7: 96000 | P7: 4800 | Q7: 91200 | R7: 62400 | S7: 28800 | T7: 0.31578947 | U7: 46023 | V7: 2026 | W7: Thursday | X7: Weekday | Y7: Y | Z7: N
A8: O1007 | B8: 46040 | C8: C007 | D8: P001 | E8: E002 | F8: Bangalore | G8: Delivered | H8: Card | I8: 4 | J8: 50000 | K8: 0.1 | L8: Laptop | M8: Priya Sharma | N8: Future Systems | O8: 200000 | P8: 20000 | Q8: 180000 | R8: 156000 | S8: 24000 | T8: 0.13333333 | U8: 46023 | V8: 2026 | W8: Sunday | X8: Weekned | Y8: Y | Z8: N
A9: O1008 | B9: 46042 | C9: C008 | D9: P002 | E9: E003 | F9: Pune | G9: Delivered | H9: Online | I9: 10 | J9: 25000 | K9: 0.12 | L9: Monitor | M9: Arjun Reddy | N9: Prime Digital | O9: 250000 | P9: 30000 | Q9: 220000 | R9: 190000 | S9: 30000 | T9: 0.13636364 | U9: 46023 | V9: 2026 | W9: Tuesday | X9: Weekday | Y9: Y | Z9: N
A10: O1009 | B10: 46044 | C10: C009 | D10: P003 | E10: E004 | F10: Hyderabad | G10: Delivered | H10: UPI | I10: 25 | J10: 5000 | K10: 0.05 | L10: Keyboard | M10: Sneha Patel | N10: Smart World | O10: 125000 | P10: 6250 | Q10: 118750 | R10: 87500 | S10: 31250 | T10: 0.26315789 | U10: 46023 | V10: 2026 | W10: Thursday | X10: Weekday | Y10: Y | Z10: N
A11: O1010 | B11: 46047 | C11: C010 | D11: P004 | E11: E005 | F11: Chennai | G11: Delivered | H11: Cash | I11: 30 | J11: 2000 | K11: 0 | L11: Mouse | M11: Kiran Rao | N11: NextGen Solutions | O11: 60000 | P11: 0 | Q11: 60000 | R11: 36000 | S11: 24000 | T11: 0.4 | U11: 46023 | V11: 2026 | W11: Sunday | X11: Weekned | Y11: Y | Z11: N
A12: O1011 | B12: 46050 | C12: C001 | D12: P005 | E12: E001 | F12: Bangalore | G12: Delivered | H12: Card | I12: 7 | J12: 35000 | K12: 0.1 | L12: Printer | M12: Rahul Kumar | N12: ABC Technologies | O12: 245000 | P12: 24500 | Q12: 220500 | R12: 189000 | S12: 31500 | T12: 0.14285714 | U12: 46023 | V12: 2026 | W12: Wednesday | X12: Weekday | Y12: Y | Z12: N
A13: O1012 | B13: 46052 | C13: C002 | D13: P006 | E13: E006 | F13: Pune | G13: Delivered | H13: UPI | I13: 15 | J13: 8000 | K13: 0.05 | L13: Headset | M13: Anjali Singh | N13: Sri Lakshmi Traders | O13: 120000 | P13: 6000 | Q13: 114000 | R13: 78000 | S13: 36000 | T13: 0.31578947 | U13: 46023 | V13: 2026 | W13: Friday | X13: Weekday | Y13: Y | Z13: N
... A121: O1120 | B121: 46380 | C121: C010 | D121: P006 | E121: E002 | F121: Chennai | G121: Delivered | H121: UPI | I121: 34 | J121: 8000 | K121: 0.05 | L121: Headset | M121: Priya Sharma | N121: NextGen Solutions | O121: 272000 | P121: 13600 | Q121: 258400 | R121: 176800 | S121: 81600 | T121: 0.31578947 | U121: 46357 | V121: 2026 | W121: Thursday | X121: Weekday | Y121: Y | Z121: N

Sheet Products (2)
A1: Product ID | B1: Product Name | C1: Category | D1: Brand | E1: Standard Cost | F1: Selling Price
A2: P001 | B2: Laptop | C2: Computers | D2: Dell | E2: 39000 | F2: 50000
A3: P002 | B3: Monitor | C3: Displays | D3: LG | E3: 19000 | F3: 25000
A4: P003 | B4: Keyboard | C4: Accessories | D4: Logitech | E4: 3500 | F4: 5000
A5: P004 | B5: Mouse | C5: Accessories | D5: Logitech | E5: 1200 | F5: 2000
A6: P005 | B6: Printer | C6: Printers | D6: HP | E6: 27000 | F6: 35000
A7: P006 | B7: Headset | C7: Accessories | D7: Boat | E7: 5200 | F7: 8000

Sheet Customers (2)
A1: Customer ID | B1: Customer Name | C1: Customer Type | D1: City | E1: State
A2: C001 | B2: ABC Technologies | C2: Corporate | D2: Hyderabad | E2: Telangana
A3: C002 | B3: Sri Lakshmi Traders | C3: Business | D3: Chennai | E3: Tamil Nadu
A4: C003 | B4: Vertex Solutions | C4: Corporate | D4: Bangalore | E4: Karnataka
A5: C004 | B5: Royal Enterprises | C5: Business | D5: Pune | E5: Maharashtra
A6: C005 | B6: TechNova Pvt Ltd | C6: Corporate | D6: Hyderabad | E6: Telangana
A7: C006 | B7: Metro Computers | C7: Retail | D7: Chennai | E7: Tamil Nadu
A8: C007 | B8: Future Systems | C8: Corporate | D8: Bangalore | E8: Karnataka
A9: C008 | B9: Prime Digital | C9: Business | D9: Pune | E9: Maharashtra
A10: C009 | B10: Smart World | C10: Retail | D10: Hyderabad | E10: Telangana
A11: C010 | B11: NextGen Solutions | C11: Corporate | D11: Chennai | E11: Tamil Nadu

Sheet Targets (2)
A1: Month | B1: Region | C1: Sales Target
A2: 46023 | B2: Hyderabad | C2: 500000
A3: 46023 | B3: Chennai | C3: 500000
A4: 46023 | B4: Bangalore | C4: 450000
A5: 46023 | B5: Pune | C5: 450000
A6: 46054 | B6: Hyderabad | C6: 500000
A7: 46054 | B7: Chennai | C7: 500000
A8: 46054 | B8: Bangalore | C8: 450000
A9: 46054 | B9: Pune | C9: 450000
A10: 46082 | B10: Hyderabad | C10: 550000
A11: 46082 | B11: Chennai | C11: 550000
A12: 46082 | B12: Bangalore | C12: 500000
A13: 46082 | B13: Pune | C13: 500000
... A37: 46266 | B37: Pune | C37: 650000

Sheet Returns (2)
A1: Return ID | B1: Order ID | C1: Return Date | D1: Return Qty | E1: Return Reason
A2: R001 | B2: O1008 | C2: 46078 | D2: 2 | E2: Damaged
A3: R002 | B3: O1015 | C3: 46093 | D3: 3 | E3: Wrong Product
A4: R003 | B4: O1022 | C4: 46101 | D4: 5 | E4: Customer Cancellation
A5: R004 | B5: O1031 | C5: 46130 | D5: 1 | E5: Damaged
A6: R005 | B6: O1040 | C6: 46162 | D6: 4 | E6: Defective
A7: R006 | B7: O1055 | C7: 46223 | D7: 2 | E7: Wrong Product

Sheet Employees
A1: Employee ID | B1: Employee Name | C1: Department | D1: Joining Date
A2: E001 | B2: Rahul Kumar | C2: Sales | D2: 45458
A3: E002 | B3: Priya Sharma | C3: Sales | D3: 45514
A4: E003 | B4: Arjun Reddy | C4: Sales | D4: 45677
A5: E004 | B5: Sneha Patel | C5: Sales | D5: 45721
A6: E005 | B6: Kiran Rao | C6: Sales | D6: 45789
A7: E006 | B7: Anjali Singh | C7: Sales | D7: 45856
